[Sun Jul 07 20:50:03 2013] [notice] caught SIGTERM, shutting down
[Sun Jul 07 20:50:08 2013] [warn] mod_wsgi: Compiled for Python/2.7.1.
[Sun Jul 07 20:50:08 2013] [warn] mod_wsgi: Runtime using Python/2.7.5.
[Sun Jul 07 20:50:08 2013] [notice] Apache/2.2.17 (Unix) mod_wsgi/3.3 Python/2.7.5 configured -- resuming normal operations
[Sun Jul 07 20:50:29 2013] [notice] caught SIGTERM, shutting down
[Sun Jul 07 20:50:34 2013] [warn] mod_wsgi: Compiled for Python/2.7.1.
[Sun Jul 07 20:50:34 2013] [warn] mod_wsgi: Runtime using Python/2.7.5.
[Sun Jul 07 20:50:34 2013] [notice] Apache/2.2.17 (Unix) mod_wsgi/3.3 Python/2.7.5 configured -- resuming normal operations
[Sun Jul 07 13:51:27 2013] [error] /home/plocker/lib/python2.7/mailchimp/settings.py:136: MailchimpWarning: you did not define a MAILCHIMP_WEBHOOK_KEY setting. django-mailchimp will create a random one by itself
[Sun Jul 07 13:51:27 2013] [error]   "django-mailchimp will create a random one by itself", MailchimpWarning)
[Sun Jul 07 13:51:34 2013] [error] /home/plocker/lib/python2.7/mailchimp/settings.py:136: MailchimpWarning: you did not define a MAILCHIMP_WEBHOOK_KEY setting. django-mailchimp will create a random one by itself
[Sun Jul 07 13:51:34 2013] [error]   "django-mailchimp will create a random one by itself", MailchimpWarning)
[Sun Jul 07 17:57:07 2013] [error] [client 127.0.0.1] mod_wsgi (pid=733236): Exception occurred processing WSGI script '/home/plocker/webapps/django/myproject/myproject/wsgi.py'.
[Sun Jul 07 17:57:07 2013] [error] [client 127.0.0.1] IOError: failed to write data
[Sun Jul 07 17:58:40 2013] [error] [client 127.0.0.1] mod_wsgi (pid=733237): Exception occurred processing WSGI script '/home/plocker/webapps/django/myproject/myproject/wsgi.py'.
[Sun Jul 07 17:58:40 2013] [error] [client 127.0.0.1] Traceback (most recent call last):
[Sun Jul 07 17:58:40 2013] [error] [client 127.0.0.1]   File "/home/plocker/webapps/django/lib/python2.7/django/core/handlers/wsgi.py", line 241, in __call__
[Sun Jul 07 17:58:40 2013] [error] [client 127.0.0.1] mod_wsgi (pid=733236): Exception occurred processing WSGI script '/home/plocker/webapps/django/myproject/myproject/wsgi.py'.
[Sun Jul 07 17:58:40 2013] [error] [client 127.0.0.1] Traceback (most recent call last):
[Sun Jul 07 17:58:40 2013] [error] [client 127.0.0.1]   File "/home/plocker/webapps/django/lib/python2.7/django/core/handlers/wsgi.py", line 241, in __call__
[Sun Jul 07 17:58:40 2013] [error] [client 127.0.0.1]     response = self.get_response(request)
[Sun Jul 07 17:58:40 2013] [error] [client 127.0.0.1]   File "/home/plocker/webapps/django/lib/python2.7/django/core/handlers/base.py", line 179, in get_response
[Sun Jul 07 17:58:40 2013] [error] [client 127.0.0.1]     response = self.get_response(request)
[Sun Jul 07 17:58:40 2013] [error] [client 127.0.0.1]   File "/home/plocker/webapps/django/lib/python2.7/django/core/handlers/base.py", line 179, in get_response
[Sun Jul 07 17:58:40 2013] [error] [client 127.0.0.1]     response = self.handle_uncaught_exception(request, resolver, sys.exc_info())
[Sun Jul 07 17:58:40 2013] [error] [client 127.0.0.1]   File "/home/plocker/webapps/django/lib/python2.7/django/core/handlers/base.py", line 228, in handle_uncaught_exception
[Sun Jul 07 17:58:40 2013] [error] [client 127.0.0.1]     return callback(request, **param_dict)
[Sun Jul 07 17:58:40 2013] [error] [client 127.0.0.1]   File "/home/plocker/webapps/django/lib/python2.7/django/utils/decorators.py", line 91, in _wrapped_view
[Sun Jul 07 17:58:40 2013] [error] [client 127.0.0.1]     response = self.handle_uncaught_exception(request, resolver, sys.exc_info())
[Sun Jul 07 17:58:40 2013] [error] [client 127.0.0.1]   File "/home/plocker/webapps/django/lib/python2.7/django/core/handlers/base.py", line 228, in handle_uncaught_exception
[Sun Jul 07 17:58:40 2013] [error] [client 127.0.0.1]     return callback(request, **param_dict)
[Sun Jul 07 17:58:40 2013] [error] [client 127.0.0.1]   File "/home/plocker/webapps/django/lib/python2.7/django/utils/decorators.py", line 91, in _wrapped_view
[Sun Jul 07 17:58:40 2013] [error] [client 127.0.0.1]     response = view_func(request, *args, **kwargs)
[Sun Jul 07 17:58:40 2013] [error] [client 127.0.0.1]     response = view_func(request, *args, **kwargs)
[Sun Jul 07 17:58:40 2013] [error] [client 127.0.0.1]   File "/home/plocker/webapps/django/lib/python2.7/django/views/defaults.py", line 32, in server_error
[Sun Jul 07 17:58:40 2013] [error] [client 127.0.0.1]   File "/home/plocker/webapps/django/lib/python2.7/django/views/defaults.py", line 32, in server_error
[Sun Jul 07 17:58:40 2013] [error] [client 127.0.0.1]     t = loader.get_template(template_name) # You need to create a 500.html template.
[Sun Jul 07 17:58:40 2013] [error] [client 127.0.0.1]     t = loader.get_template(template_name) # You need to create a 500.html template.
[Sun Jul 07 17:58:40 2013] [error] [client 127.0.0.1]   File "/home/plocker/webapps/django/lib/python2.7/django/template/loader.py", line 145, in get_template
[Sun Jul 07 17:58:40 2013] [error] [client 127.0.0.1]   File "/home/plocker/webapps/django/lib/python2.7/django/template/loader.py", line 145, in get_template
[Sun Jul 07 17:58:40 2013] [error] [client 127.0.0.1]     template, origin = find_template(template_name)
[Sun Jul 07 17:58:40 2013] [error] [client 127.0.0.1]     template, origin = find_template(template_name)
[Sun Jul 07 17:58:40 2013] [error] [client 127.0.0.1]   File "/home/plocker/webapps/django/lib/python2.7/django/template/loader.py", line 138, in find_template
[Sun Jul 07 17:58:40 2013] [error] [client 127.0.0.1]     raise TemplateDoesNotExist(name)
[Sun Jul 07 17:58:40 2013] [error] [client 127.0.0.1] TemplateDoesNotExist: 500.html
[Sun Jul 07 17:58:40 2013] [error] [client 127.0.0.1]   File "/home/plocker/webapps/django/lib/python2.7/django/template/loader.py", line 138, in find_template
[Sun Jul 07 17:58:40 2013] [error] [client 127.0.0.1]     raise TemplateDoesNotExist(name)
[Sun Jul 07 17:58:40 2013] [error] [client 127.0.0.1] TemplateDoesNotExist: 500.html
